<?xml version="1.0"?>
<!-- DO NOT EDIT: Generated from p2.sdf.jinja -->
<sdf version='1.10'>
  <model name='s1_copter'>
    <pose>0 0 0 0 0 0</pose> <!-- Position of model inertial frame relative to gazebo inertial frame -->
<!-- Base link (Fuselage + Wings) -->
    <link name='base_link'>
      <!-- 0 0 0.115 0 0 0 -->
      <pose>0 0 0.115 0 0 0</pose> <!-- Position of S1 CG Frame relative to inertial frame. sitl flight controller is at base link origin. therefore CG should be at base link origin -->
      <inertial>
        <pose>0 0 0 0 0 0</pose> <!-- Position of inertia tensor relative to base_link frame (center of gravity) should be at base link origin -->
        <mass>24.0</mass>
        <inertia> <!-- Inertia characteristics of base_link -->
          <!-- Seems to be right. Check with structure/PD team-->
          <ixx>6.023</ixx>
          <ixy>0.014</ixy>
          <ixz>0.366</ixz>
          <iyy>10.405</iyy>
          <iyz>0.0</iyz>
          <izz>16.231</izz>
        </inertia>
      </inertial>
      <collision name='base_link_collision'> <!-- Collision geometry for base_link -->
        <pose>0 0 0 0 0 0</pose> <!-- Frame location of collision box relative to base_link frame -->
        <geometry>
          <box>
            <size>2.3 3.4 0.38</size>
          </box>
        </geometry>
        <surface>
          <contact>
            <ode>
              <kp>100000</kp>
              <kd>1.0</kd>
              <max_vel>0.1</max_vel>
              <min_depth>0.001</min_depth>
            </ode>
          </contact>
          <friction>
            <ode/>
          </friction>
        </surface>
      </collision>
      <visual name='base_link_visual'> 
        <pose>0 0 0 0 0 0</pose>
        <geometry>
          <mesh>
            <scale>0.001 0.001 0.001</scale>
            <uri>model://s1_copter/meshes/S1_Airframe+Motoren.stl</uri>
          </mesh>
        </geometry>
        <material>
          <ambient>.175 .175 .175 1.0</ambient>
          <diffuse>.175 .175 .175 1.0</diffuse>
        </material>
      </visual>
      <gravity>1</gravity>
      <velocity_decay/>
      <self_collide>0</self_collide>
      <sensor name="imu_sensor" type="imu">
        <always_on>1</always_on>
        <update_rate>250</update_rate>
        <imu>
          <angular_velocity>
            <x>
              <noise type="gaussian">
                <mean>0</mean>
                <stddev>0.0003394</stddev>
                <dynamic_bias_stddev>3.8785e-05</dynamic_bias_stddev>
                <dynamic_bias_correlation_time>1000</dynamic_bias_correlation_time>
              </noise>
            </x>
            <y>
              <noise type="gaussian">
                <mean>0</mean>
                <stddev>0.0003394</stddev>
                <dynamic_bias_stddev>3.8785e-05</dynamic_bias_stddev>
                <dynamic_bias_correlation_time>1000</dynamic_bias_correlation_time>
              </noise>
            </y>
            <z>
              <noise type="gaussian">
                <mean>0</mean>
                <stddev>0.0003394</stddev>
                <dynamic_bias_stddev>3.8785e-05</dynamic_bias_stddev>
                <dynamic_bias_correlation_time>1000</dynamic_bias_correlation_time>
              </noise>
            </z>
          </angular_velocity>
          <linear_acceleration>
            <x>
              <noise type="gaussian">
                <mean>0</mean>
                <stddev>0.004</stddev>
                <dynamic_bias_stddev>0.006</dynamic_bias_stddev>
                <dynamic_bias_correlation_time>300</dynamic_bias_correlation_time>
              </noise>
            </x>
            <y>
              <noise type="gaussian">
                <mean>0</mean>
                <stddev>0.004</stddev>
                <dynamic_bias_stddev>0.006</dynamic_bias_stddev>
                <dynamic_bias_correlation_time>300</dynamic_bias_correlation_time>
              </noise>
            </y>
            <z>
              <noise type="gaussian">
                <mean>0</mean>
                <stddev>0.004</stddev>
                <dynamic_bias_stddev>0.006</dynamic_bias_stddev>
                <dynamic_bias_correlation_time>300</dynamic_bias_correlation_time>
              </noise>
            </z>
          </linear_acceleration>
        </imu>
      </sensor>
      <sensor name="air_pressure_sensor" type="air_pressure">
        <always_on>1</always_on>
        <update_rate>50</update_rate>
        <air_pressure>
          <pressure>
            <noise type="gaussian">
              <mean>0</mean>
              <stddev>0.01</stddev>
            </noise>
          </pressure>
        </air_pressure>
      </sensor>
      <sensor name="navsat_sensor" type="navsat">
        <always_on>1</always_on>
        <update_rate>30</update_rate>
      </sensor>
    </link>
    <!-- Nose Link Frame-->
    <link name='nose_link'>
      <pose relative_to="base_link"> 1.2 0 0 0 0 0 </pose>
    </link>
<!-- Propellers -->
    <!-- Propeller 0 (vorne links)-->
    <link name='rotor_0'>
      <pose relative_to="nose_link">-0.4481 0.97 -0.03 0.135 0 0</pose> <!-- rotation of 2° about x axis -->
      <inertial>
        <pose>0 0 0 0 0 0</pose>
        <mass>0.005</mass> <!-- This mass seems to be wrong -->
        <inertia>
          <ixx>9.75e-07</ixx>
          <ixy>0</ixy>
          <ixz>0</ixz>
          <iyy>0.000166704</iyy>
          <iyz>0</iyz>
          <izz>0.000167604</izz>
        </inertia>
      </inertial>
      <collision name='rotor_0_collision'>
        <pose>0 0 0 0 0 0</pose>
        <geometry>
          <cylinder>
            <length>0.005</length>
            <radius>0.1</radius>
          </cylinder>
        </geometry>
        <surface>
          <contact>
            <ode/>
          </contact>
          <friction>
            <ode/>
          </friction>
        </surface>
      </collision>
      <visual name='rotor_0_visual'>
        <pose>0 0 0 0 0 0</pose>
        <geometry>
          <mesh>
            <scale>0.001 0.001 0.001</scale>
            <uri>model://s1_copter/meshes/S1_Hover-Prop_CCW.stl</uri>
          </mesh>
        </geometry>
        <material>
          <ambient>0 0 1 1.0</ambient> <!-- Values for RGB values and alpha (transparency) -->
          <diffuse>0 0 1 1.0</diffuse>
        </material>
      </visual>
      <gravity>1</gravity>
      <velocity_decay/>
      <self_collide>0</self_collide>
    </link>
    <joint name='rotor_0_joint' type='revolute'>
      <child>rotor_0</child>
      <parent>base_link</parent>
      <axis>
        <xyz>0 0 1</xyz>
        <limit>
          <lower>-1e+16</lower>
          <upper>1e+16</upper>
        </limit>
        <dynamics>
          <spring_reference>0</spring_reference>
          <spring_stiffness>0</spring_stiffness>
        </dynamics>
      </axis>
    </joint>
    <!-- Propeller 1 (vorne links zwei)-->
    <link name='rotor_1'>
      <pose relative_to="nose_link">-0.9 0.97 -0.03 0 0 0</pose>
      <inertial>
        <pose>0 0 0 0 0 0</pose>
        <mass>0.005</mass>
        <inertia>
          <ixx>9.75e-07</ixx>
          <ixy>0</ixy>
          <ixz>0</ixz>
          <iyy>0.000166704</iyy>
          <iyz>0</iyz>
          <izz>0.000167604</izz>
        </inertia>
      </inertial>
      <collision name='rotor_1_collision'>
        <pose>0 0 0 0 0 0</pose>
        <geometry>
          <cylinder>
            <length>0.005</length>
            <radius>0.1</radius>
          </cylinder>
        </geometry>
        <surface>
          <contact>
            <ode/>
          </contact>
          <friction>
            <ode/>
          </friction>
        </surface>
      </collision>
      <visual name='rotor_1_visual'>
        <pose>0 0 0 0 0 0</pose>
        <geometry>
          <mesh>
            <scale>0.001 0.001 0.001</scale>
            <uri>model://s1_copter/meshes/S1_Hover-Prop_CW.stl</uri>
          </mesh>
        </geometry>
        <material>
          <ambient>0 0 1 1.0</ambient>
          <diffuse>0 0 1 1.0</diffuse>
        </material>
      </visual>
      <gravity>1</gravity>
      <velocity_decay/>
      <self_collide>0</self_collide>
    </link>
    <joint name='rotor_1_joint' type='revolute'>
      <child>rotor_1</child>
      <parent>base_link</parent>
      <axis>
        <xyz>0 0 1</xyz>
        <limit>
          <lower>-1e+16</lower>
          <upper>1e+16</upper>
        </limit>
        <dynamics>
          <spring_reference>0</spring_reference>
          <spring_stiffness>0</spring_stiffness>
        </dynamics>
      </axis>
    </joint>
    <!-- Propeller 2 (vorne links drei)-->
    <link name='rotor_2'>
      <pose relative_to="nose_link">-1.3519 0.97 -0.03 0 0 0</pose>
      <inertial>
        <pose>0 0 0 0 0 0</pose>
        <mass>0.005</mass>
        <inertia>
          <ixx>9.75e-07</ixx>
          <ixy>0</ixy>
          <ixz>0</ixz>
          <iyy>0.000166704</iyy>
          <iyz>0</iyz>
          <izz>0.000167604</izz>
        </inertia>
      </inertial>
      <collision name='rotor_2_collision'>
        <pose>0 0 0 0 0 0</pose>
        <geometry>
          <cylinder>
            <length>0.005</length>
            <radius>0.1</radius>
          </cylinder>
        </geometry>
        <surface>
          <contact>
            <ode/>
          </contact>
          <friction>
            <ode/>
          </friction>
        </surface>
      </collision>
      <visual name='rotor_2_visual'>
        <pose>0 0 0 0 0 0</pose>
        <geometry>
          <mesh>
            <scale>0.001 0.001 0.001</scale>
            <uri>model://s1_copter/meshes/S1_Hover-Prop_CCW.stl</uri>
          </mesh>
        </geometry>
        <material>
          <ambient>0 0 1 1.0</ambient>
          <diffuse>0 0 1 1.0</diffuse>
        </material>
      </visual>
      <gravity>1</gravity>
      <velocity_decay/>
      <self_collide>0</self_collide>
    </link>
    <joint name='rotor_2_joint' type='revolute'>
      <child>rotor_2</child>
      <parent>base_link</parent>
      <axis>
        <xyz>0 0 1</xyz>
        <limit>
          <lower>-1e+16</lower>
          <upper>1e+16</upper>
        </limit>
        <dynamics>
          <spring_reference>0</spring_reference>
          <spring_stiffness>0</spring_stiffness>
        </dynamics>
      </axis>
    </joint>
    <!-- Propeller 3 (vorne links 4)-->
    <link name='rotor_3'>
      <pose relative_to="nose_link">-2.1 0.97 -0.03 -0.135 0 0</pose> <!-- rotation of -2° about x axis -->
      <inertial>
        <pose>0 0 0 0 0 0</pose>
        <mass>0.005</mass>
        <inertia>
          <ixx>9.75e-07</ixx>
          <ixy>0</ixy>
          <ixz>0</ixz>
          <iyy>0.000166704</iyy>
          <iyz>0</iyz>
          <izz>0.000167604</izz>
        </inertia>
      </inertial>
      <collision name='rotor_3_collision'>
        <pose>0 0 0 0 0 0</pose>
        <geometry>
          <cylinder>
            <length>0.005</length>
            <radius>0.1</radius>
          </cylinder>
        </geometry>
        <surface>
          <contact>
            <ode/>
          </contact>
          <friction>
            <ode/>
          </friction>
        </surface>
      </collision>
      <visual name='rotor_3_visual'>
        <pose>0 0 0 0 0 0</pose>
        <geometry>
          <mesh>
            <scale>0.001 0.001 0.001</scale>
            <uri>model://s1_copter/meshes/S1_Hover-Prop_CW.stl</uri>
          </mesh>
        </geometry>
        <material>
          <ambient>0 0 1 1.0</ambient>
          <diffuse>0 0 1 1.0</diffuse>
        </material>
      </visual>
      <gravity>1</gravity>
      <velocity_decay/>
      <self_collide>0</self_collide>
    </link>
    <joint name='rotor_3_joint' type='revolute'>
      <child>rotor_3</child>
      <parent>base_link</parent>
      <axis>
        <xyz>0 0 1</xyz>
        <limit>
          <lower>-1e+16</lower>
          <upper>1e+16</upper>
        </limit>
        <dynamics>
          <spring_reference>0</spring_reference>
          <spring_stiffness>0</spring_stiffness>
        </dynamics>
      </axis>
    </joint>
    <!-- Propeller 4 (vorne rechts 1)-->
    <link name='rotor_4'>
      <pose relative_to="nose_link">-0.4481	-0.97	-0.03 -0.135 0 0</pose> <!-- rotation of -2° about x axis -->
      <inertial>
        <pose>0 0 0 0 0 0</pose>
        <mass>0.005</mass>
        <inertia>
          <ixx>9.75e-07</ixx>
          <ixy>0</ixy>
          <ixz>0</ixz>
          <iyy>0.000166704</iyy>
          <iyz>0</iyz>
          <izz>0.000167604</izz>
        </inertia>
      </inertial>
      <collision name='rotor_4_collision'>
        <pose>0 0 0 0 0 0</pose>
        <geometry>
          <cylinder>
            <length>0.005</length>
            <radius>0.1</radius>
          </cylinder>
        </geometry>
        <surface>
          <contact>
            <ode/>
          </contact>
          <friction>
            <ode/>
          </friction>
        </surface>
      </collision>
      <visual name='rotor_4_visual'>
        <pose>0 0 0 0 0 0</pose>
        <geometry>
          <mesh>
            <scale>0.001 0.001 0.001</scale>
            <uri>model://s1_copter/meshes/S1_Hover-Prop_CW.stl</uri>
          </mesh>
        </geometry>
        <material>
          <ambient>0 0 1 1.0</ambient>
          <diffuse>0 0 1 1.0</diffuse>
        </material>
      </visual>
      <gravity>1</gravity>
      <velocity_decay/>
      <self_collide>0</self_collide>
    </link>
    <joint name='rotor_4_joint' type='revolute'>
      <child>rotor_4</child>
      <parent>base_link</parent>
      <axis>
        <xyz>0 0 1</xyz>
        <limit>
          <lower>-1e+16</lower>
          <upper>1e+16</upper>
        </limit>
        <dynamics>
          <spring_reference>0</spring_reference>
          <spring_stiffness>0</spring_stiffness>
        </dynamics>
      </axis>
    </joint>
    <!-- Propeller 5 (vorne rechts 2)-->
    <link name='rotor_5'>
      <pose relative_to="nose_link">-0.9 -0.97 -0.03 0 0 0</pose>
      <inertial>
        <pose>0 0 0 0 0 0</pose>
        <mass>0.005</mass>
        <inertia>
          <ixx>9.75e-07</ixx>
          <ixy>0</ixy>
          <ixz>0</ixz>
          <iyy>0.000166704</iyy>
          <iyz>0</iyz>
          <izz>0.000167604</izz>
        </inertia>
      </inertial>
      <collision name='rotor_5_collision'>
        <pose>0 0 0 0 0 0</pose>
        <geometry>
          <cylinder>
            <length>0.005</length>
            <radius>0.1</radius>
          </cylinder>
        </geometry>
        <surface>
          <contact>
            <ode/>
          </contact>
          <friction>
            <ode/>
          </friction>
        </surface>
      </collision>
      <visual name='rotor_5_visual'>
        <pose>0 0 0 0 0 0</pose>
        <geometry>
          <mesh>
            <scale>0.001 0.001 0.001</scale>
            <uri>model://s1_copter/meshes/S1_Hover-Prop_CCW.stl</uri>
          </mesh>
        </geometry>
        <material>
          <ambient>0 0 1 1.0</ambient>
          <diffuse>0 0 1 1.0</diffuse>
        </material>
      </visual>
      <gravity>1</gravity>
      <velocity_decay/>
      <self_collide>0</self_collide>
    </link>
    <joint name='rotor_5_joint' type='revolute'>
      <child>rotor_5</child>
      <parent>base_link</parent>
      <axis>
        <xyz>0 0 1</xyz>
        <limit>
          <lower>-1e+16</lower>
          <upper>1e+16</upper>
        </limit>
        <dynamics>
          <spring_reference>0</spring_reference>
          <spring_stiffness>0</spring_stiffness>
        </dynamics>
      </axis>
    </joint>
    <!-- Propeller 6 (vorne rechts 3)-->
    <link name='rotor_6'>
      <pose relative_to="nose_link">-1.3519	-0.97	-0.03 0 0 0</pose>
      <inertial>
        <pose>0 0 0 0 0 0</pose>
        <mass>0.005</mass> <!-- This mass seems to be wrong -->
        <inertia>
          <ixx>9.75e-07</ixx>
          <ixy>0</ixy>
          <ixz>0</ixz>
          <iyy>0.000166704</iyy>
          <iyz>0</iyz>
          <izz>0.000167604</izz>
        </inertia>
      </inertial>
      <collision name='rotor_6_collision'>
        <pose>0 0 0 0 0 0</pose>
        <geometry>
          <cylinder>
            <length>0.005</length>
            <radius>0.1</radius>
          </cylinder>
        </geometry>
        <surface>
          <contact>
            <ode/>
          </contact>
          <friction>
            <ode/>
          </friction>
        </surface>
      </collision>
      <visual name='rotor_6_visual'>
        <pose>0 0 0 0 0 0</pose>
        <geometry>
          <mesh>
            <scale>0.001 0.001 0.001</scale>
            <uri>model://s1_copter/meshes/S1_Hover-Prop_CW.stl</uri>
          </mesh>
        </geometry>
        <material>
          <ambient>0 0 1 1.0</ambient> <!-- Values for RGB values and alpha (transparency) -->
          <diffuse>0 0 1 1.0</diffuse>
        </material>
      </visual>
      <gravity>1</gravity>
      <velocity_decay/>
      <self_collide>0</self_collide>
    </link>
    <joint name='rotor_6_joint' type='revolute'>
      <child>rotor_6</child>
      <parent>base_link</parent>
      <axis>
        <xyz>0 0 1</xyz>
        <limit>
          <lower>-1e+16</lower>
          <upper>1e+16</upper>
        </limit>
        <dynamics>
          <spring_reference>0</spring_reference>
          <spring_stiffness>0</spring_stiffness>
        </dynamics>
      </axis>
    </joint>
    <!-- Propeller 7 (vorne rechts 4)-->
    <link name='rotor_7'>
      <pose relative_to="nose_link">-2.1 -0.97 -0.03 0.135 0 0</pose> <!-- rotation of 2° about x axis -->
      <inertial>
        <pose>0 0 0 0 0 0</pose>
        <mass>0.005</mass> <!-- This mass seems to be wrong -->
        <inertia>
          <ixx>9.75e-07</ixx>
          <ixy>0</ixy>
          <ixz>0</ixz>
          <iyy>0.000166704</iyy>
          <iyz>0</iyz>
          <izz>0.000167604</izz>
        </inertia>
      </inertial>
      <collision name='rotor_7_collision'>
        <pose>0 0 0 0 0 0</pose>
        <geometry>
          <cylinder>
            <length>0.005</length>
            <radius>0.1</radius>
          </cylinder>
        </geometry>
        <surface>
          <contact>
            <ode/>
          </contact>
          <friction>
            <ode/>
          </friction>
        </surface>
      </collision>
      <visual name='rotor_7_visual'>
        <pose>0 0 0 0 0 0</pose>
        <geometry>
          <mesh>
            <scale>0.001 0.001 0.001</scale>
            <uri>model://s1_copter/meshes/S1_Hover-Prop_CCW.stl</uri>
          </mesh>
        </geometry>
        <material>
          <ambient>0 0 1 1.0</ambient> <!-- Values for RGB values and alpha (transparency) -->
          <diffuse>0 0 1 1.0</diffuse>
        </material>
      </visual>
      <gravity>1</gravity>
      <velocity_decay/>
      <self_collide>0</self_collide>
    </link>
    <joint name='rotor_7_joint' type='revolute'>
      <child>rotor_7</child>
      <parent>base_link</parent>
      <axis>
        <xyz>0 0 1</xyz>
        <limit>
          <lower>-1e+16</lower>
          <upper>1e+16</upper>
        </limit>
        <dynamics>
          <spring_reference>0</spring_reference>
          <spring_stiffness>0</spring_stiffness>
        </dynamics>
      </axis>
    </joint>
    <!-- Pusher Prop left -->
    <link name='rotor_8'>
      <pose relative_to="nose_link">-2.040004 0.47 0.089 0 1.5708 0</pose> <!-- Rotation um 90° um y Achse -->
      <inertial>
        <pose>0 0 0 0 0 0</pose>
        <mass>0.005</mass>
        <inertia>
          <ixx>9.75e-07</ixx>
          <ixy>0</ixy>
          <ixz>0</ixz>
          <iyy>0.000166704</iyy>
          <iyz>0</iyz>
          <izz>0.000167604</izz>
        </inertia>
      </inertial>
      <collision name='rotor_8_collision'>
        <pose>0 0 0 0 0 0</pose>
        <geometry>
          <cylinder>
            <length>0.005</length>
            <radius>0.06</radius>
          </cylinder>
        </geometry>
        <surface>
          <contact>
            <ode/>
          </contact>
          <friction>
            <ode/>
          </friction>
        </surface>
      </collision>
      <visual name='rotor_8_visual'>
        <pose>0 0 0 0 -1.5708 0</pose>
        <geometry>
          <mesh>
            <scale>0.001 0.001 0.001</scale>
            <uri>model://s1/meshes/S1_Pusher-Prop_CCW.stl</uri>
          </mesh>
        </geometry>
        <material>
          <ambient>0 0 1 1.0</ambient>
          <diffuse>0 0 1 1.0</diffuse>
        </material>
      </visual>
      <gravity>1</gravity>
      <velocity_decay/>
      <self_collide>0</self_collide>
    </link>
    <joint name='rotor_8_joint' type='revolute'>
      <pose>0.0 0 0.0 0 0 0</pose>
      <child>rotor_8</child>
      <parent>base_link</parent>
      <axis>
        <xyz>0 0 1</xyz>
        <limit>
          <lower>-1e+16</lower>
          <upper>1e+16</upper>
        </limit>
        <dynamics>
          <spring_reference>0</spring_reference>
          <spring_stiffness>0</spring_stiffness>
        </dynamics>
      </axis>
    </joint>
    <!-- Pusher Prop right -->
    <link name='rotor_9'>
      <pose relative_to="nose_link">-2.040004 -0.47 0.089 0 1.5708 0</pose>
      <inertial>
        <pose>0 0 0 0 0 0</pose>
        <mass>0.005</mass>
        <inertia>
          <ixx>9.75e-07</ixx>
          <ixy>0</ixy>
          <ixz>0</ixz>
          <iyy>0.000166704</iyy>
          <iyz>0</iyz>
          <izz>0.000167604</izz>
        </inertia>
      </inertial>
      <collision name='rotor_9'>
        <pose>0 0 0 0 0 0</pose>
        <geometry>
          <cylinder>
            <length>0.005</length>
            <radius>0.06</radius>
          </cylinder>
        </geometry>
        <surface>
          <contact>
            <ode/>
          </contact>
          <friction>
            <ode/>
          </friction>
        </surface>
      </collision>
      <visual name='rotor_9_visual'>
        <pose>0 0 0 0 -1.5708 0</pose>
        <geometry>
          <mesh>
            <scale>0.001 0.001 0.001</scale>
            <uri>model://s1/meshes/S1_Pusher-Prop_CW.stl</uri>
          </mesh>
        </geometry>
        <material>
          <ambient>0 0 1 1.0</ambient>
          <diffuse>0 0 1 1.0</diffuse>
        </material>
      </visual>
      <gravity>1</gravity>
      <velocity_decay/>
      <self_collide>0</self_collide>
    </link>
    <joint name='rotor_9_joint' type='revolute'>
      <pose>0.0 0 0.0 0 0 0</pose>
      <child>rotor_9</child>
      <parent>base_link</parent>
      <axis>
        <xyz>0 0 1</xyz>
        <limit>
          <lower>-1e+16</lower>
          <upper>1e+16</upper>
        </limit>
        <dynamics>
          <spring_reference>0</spring_reference>
          <spring_stiffness>0</spring_stiffness>
        </dynamics>
      </axis>
    </joint>

    <!-- Control Surfaces -->
    <link name="left_aileron">
      <pose relative_to="nose_link">-1.907064 1.0913 0.102813 0 0 0</pose>
      <inertial>
        <mass>0.00000001</mass>
        <inertia>
          <ixx>0.000001</ixx>
          <ixy>0.0</ixy>
          <iyy>0.000001</iyy>
          <ixz>0.0</ixz>
          <iyz>0.0</iyz>
          <izz>0.000001</izz>
        </inertia>
      </inertial>
      <visual name='left_aileron_visual'>
        <pose>0.707064 -1.0913 -0.102813 0 0 0</pose>
        <geometry>
          <mesh>
            <scale>0.001 0.001 0.001</scale>
            <uri>model://s1_copter/meshes/S1_Aileron_Links.stl</uri>
          </mesh>
        </geometry>
        <material>
          <ambient>0 0 1 1.0</ambient>
          <diffuse>0 0 1 1.0</diffuse>
        </material>
      </visual>
    </link>
    <link name="right_aileron">
      <pose relative_to="nose_link">-1.907064 -1.0913 0.102813 0 0 0</pose>
      <inertial>
        <mass>0.00000001</mass>
        <inertia>
          <ixx>0.000001</ixx>
          <ixy>0.0</ixy>
          <iyy>0.000001</iyy>
          <ixz>0.0</ixz>
          <iyz>0.0</iyz>
          <izz>0.000001</izz>
        </inertia>
      </inertial>
      <visual name='right_aileron_visual'>
        <pose>0.707064 1.0913 -0.102813 0 0 0</pose>
        <geometry>
          <mesh>
            <scale>0.001 0.001 0.001</scale>
            <uri>model://s1_copter/meshes/S1_Aileron_Rechts.stl</uri>
          </mesh>
        </geometry>
        <material>
          <ambient>0 0 1 1.0</ambient>
          <diffuse>0 0 1 1.0</diffuse>
        </material>
      </visual>
    </link>
    <link name="left_elevon"> <!-- This should be elevator not elevon -->
      <inertial>
        <mass>0.00000001</mass>
        <inertia>
          <ixx>0.000001</ixx>
          <ixy>0.0</ixy>
          <iyy>0.000001</iyy>
          <ixz>0.0</ixz>
          <iyz>0.0</iyz>
          <izz>0.000001</izz>
        </inertia>
      </inertial>
      <pose relative_to="nose_link">-0.210379 0.5575 -0.051241 0 0 0</pose>
      <visual name='left_elevon_visual'>
        <pose>-0.989621 -0.5575 0.051241 0 0 0</pose>
        <geometry>
          <mesh>
            <scale>0.001 0.001 0.001</scale>
            <uri>model://s1_copter/meshes/S1_Elevator_Links.stl</uri>
          </mesh>
        </geometry>
        <material>
          <ambient>0 0 1 1.0</ambient>
          <diffuse>0 0 1 1.0</diffuse>
        </material>
      </visual>
    </link>
    <link name="right_elevon">
      <inertial>
        <mass>0.00000001</mass>
        <inertia>
          <ixx>0.000001</ixx>
          <ixy>0.0</ixy>
          <iyy>0.000001</iyy>
          <ixz>0.0</ixz>
          <iyz>0.0</iyz>
          <izz>0.000001</izz>
        </inertia>
      </inertial>
      <pose relative_to="nose_link">-0.204513 -0.85 -0.052616 0 0 0</pose>
      <visual name='right_elevon_visual'>
        <pose>-0.995487 0.85 0.052616 0 0 0</pose>
        <geometry>
          <mesh>
            <scale>0.001 0.001 0.001</scale>
            <uri>model://s1_copter/meshes/S1_Elevator_Rechts.stl</uri>
          </mesh>
        </geometry>
        <material>
          <ambient>0 0 1 1.0</ambient>
          <diffuse>0 0 1 1.0</diffuse>
        </material>
      </visual>
    </link>

    <!--  Servos for Control Surfaces -->
    <!-- Elevators -->
    <joint name='servo_0' type='revolute'>
      <parent>base_link</parent>
      <child>left_elevon</child>
      <axis>
        <xyz>0 1 0</xyz>
        <limit>
          <lower>-1.57</lower>
          <upper>1.57</upper>
        </limit>
        <dynamics>
          <damping>0.100</damping>
        </dynamics>
      </axis>
      <physics>
        <ode>
          <implicit_spring_damper>1</implicit_spring_damper>
        </ode>
      </physics>
    </joint>
    <joint name='servo_1' type='revolute'>
      <parent>base_link</parent>
      <child>right_elevon</child>
      <axis>
        <xyz>0 1 0</xyz>
        <limit>
          <lower>-1.57</lower>
          <upper>1.57</upper>
        </limit>
        <dynamics>
          <damping>0.100</damping>
        </dynamics>
      </axis>
      <physics>
        <ode>
          <implicit_spring_damper>1</implicit_spring_damper>
        </ode>
      </physics>
    </joint>
    <!-- Ailerons -->
    <joint name='servo_2' type='revolute'>
      <parent>base_link</parent>
      <child>left_aileron</child>
      <axis>
        <xyz>0 1 0</xyz>
        <limit>
          <lower>-0.53</lower>
          <upper>0.53</upper>
        </limit>
        <dynamics>
          <damping>0.100</damping>
        </dynamics>
      </axis>
      <physics>
        <ode>
          <implicit_spring_damper>1</implicit_spring_damper>
        </ode>
      </physics>
    </joint>
    <joint name='servo_3' type='revolute'>
      <parent>base_link</parent>
      <child>right_aileron</child>
      <axis>
        <xyz>0 1 0</xyz>
        <limit>
          <lower>-0.53</lower>
          <upper>0.53</upper>
        </limit>
        <dynamics>
          <damping>0.100</damping>
        </dynamics>
      </axis>
      <physics>
        <ode>
          <implicit_spring_damper>1</implicit_spring_damper>
        </ode>
      </physics>
    </joint>
<!-- Wing Aerodynamics -->
    <!-- Canard -->
    <plugin filename="gz-sim-lift-drag-system" name="gz::sim::systems::LiftDrag">
     <!-- Canard Left-->
      <a0>-0.0175</a0> <!--__ corny: -2.3deg or -1deg-->
      <cla>4.926</cla>
      <cda>0.5647</cda>
      <cma>0.0</cma> <!--__corny: -4.6, p4: 0-->
      <alpha_stall>5.2443</alpha_stall> <!-- <14deg for safety, actually 16.2deg overal config-->
      <cla_stall>-5.766</cla_stall> <!--__corny: -5.766, p4: -2.1001, big difference-->
      <cda_stall>1.12</cda_stall>
      <cma_stall>0</cma_stall> <!-- nicht modellierbar-->
      <cp>1.0554 0.584509 -0.059526</cp> <!-- cp wird im neuen Gazebo relativ zu dem hier genannten link definiert (hier base link) -->
      <!-- <cp>-0.146 0.584509 -0.059526</cp> relative to nose link --> 
      <area>0.207</area> <!-- __corny value for both together?-->
      <air_density>1.2</air_density>
      <forward>1 0 0</forward> <!-- gefaked von rc_cessna Seitenleitwerk -->
      <upward>0 1 0</upward> <!-- gefaked von rc_cessna Seitenleitwerk -->
      <link_name>base_link</link_name> <!--_relativ zu diesem Link ist zB cp definiert! -->
      <control_joint_name>servo_0</control_joint_name>
      <control_joint_rad_to_cl>-0.5687</control_joint_rad_to_cl> <!-- __corny: -0.5687, p4: -1.128, big difference-->
    </plugin>
    <plugin
      filename="gz-sim-joint-position-controller-system" name="gz::sim::systems::JointPositionController">
      <joint_name>servo_0</joint_name>
      <sub_topic>servo_0</sub_topic>
    </plugin>
    <plugin filename="gz-sim-lift-drag-system" name="gz::sim::systems::LiftDrag">
      <!-- Canard Right-->
      <a0>-0.0175</a0>
      <cla>4.926</cla>
      <cda>0.5647</cda>
      <cma>0.0</cma> <!--__corny: -4.6, p4: 0-->
      <alpha_stall>5.2443</alpha_stall> <!-- <14deg for safety, actually 16.2deg overal config-->
      <cla_stall>-5.766</cla_stall> <!--__corny: -5.766, p4: -2.1001, big difference-->
      <cda_stall>1.12</cda_stall>
      <cma_stall>0</cma_stall> <!-- nicht modellierbar-->
      <!-- <cp>0.57 0.28 0</cp> -->
      <cp>1.0554 -0.584509	-0.059526</cp> <!-- +/- front/rear left/right up/down-->
      <!-- <cp>-0.146 -0.584509 -0.059526</cp> relativ zu nose_link-->
      <area>0.207</area>
      <air_density>1.2</air_density>
      <forward>1 0 0</forward> <!-- gefaked von rc_cessna Seitenleitwerk -->
      <upward>0 1 0</upward> <!-- gefaked von rc_cessna Seitenleitwerk -->
      <link_name>base_link</link_name>
      <control_joint_name>servo_1</control_joint_name>
      <control_joint_rad_to_cl>-0.5687</control_joint_rad_to_cl> <!-- __corny: -0.5687, p4: -1.128, big difference-->
    </plugin>
    <plugin
      filename="gz-sim-joint-position-controller-system" name="gz::sim::systems::JointPositionController">
      <joint_name>servo_1</joint_name>
      <sub_topic>servo_1</sub_topic>
    </plugin>
    <!-- Main Wing -->
    <plugin filename="gz-sim-lift-drag-system" name="gz::sim::systems::LiftDrag">
        <!-- Main Wing Left -->
      <a0>0.</a0>
      <cla>4.419</cla>
      <cda>0.5647</cda>
      <cma>0</cma> <!--__corny: -4.6, p4: 0-->
      <alpha_stall>0.2443</alpha_stall> <!-- <14deg for safety, actually 15.3deg overal config-->
      <cla_stall>-1.428</cla_stall> <!-- __corny: -1.428/rad, p4: -2.1001-->
      <cda_stall>1.12</cda_stall> <!-- __corny: 1.12, p4: 0.8362, big difference-->
      <cma_stall>0</cma_stall> <!-- nicht modellierbar -->
      <!-- <cp>-0.38 0.5 0</cp> -->
      <cp>-0.602	0.962509	0.089</cp>
      <!-- <cp>-1.802 0.962509 0.089</cp> relative to nose link-->
      <area>0.505</area>
      <air_density>1.2</air_density>
      <forward>1 0 0</forward>
      <upward>0 0 1</upward>
      <link_name>base_link</link_name>
      <control_joint_name>servo_2</control_joint_name>
      <control_joint_rad_to_cl>-0.4888</control_joint_rad_to_cl> <!-- __corny: -0.4888, p4: -0.898, big difference -->
    </plugin>
    <plugin
      filename="gz-sim-joint-position-controller-system" name="gz::sim::systems::JointPositionController">
      <joint_name>servo_2</joint_name>
      <sub_topic>servo_2</sub_topic>
    </plugin>
    <plugin filename="gz-sim-lift-drag-system" name="gz::sim::systems::LiftDrag">
      <!-- Main Wing Right-->
      <a0>0.</a0>
      <cla>4.419</cla>
      <cda>0.5647</cda>
      <cma>0</cma> <!--__corny: -4.6, p4: 0-->
      <alpha_stall>0.2443</alpha_stall> <!-- <14deg for safety, actually 15.3deg overal config-->
      <cla_stall>-1.428</cla_stall> <!-- __corny: -1.428/rad, p4: -2.1001-->
      <cda_stall>1.12</cda_stall> <!-- __corny: 1.12, p4: 0.8362, big difference-->
      <cma_stall>0</cma_stall> <!-- nicht modellierbar -->
      <!-- <cp>-0.38 0.5 0</cp> -->
      <cp>-0.602	-0.962509	0.089</cp>
      <!-- <cp>-1.802 -0.962509 0.089</cp> relative to nose link -->
      <area>0.505</area>
      <air_density>1.2</air_density>
      <forward>1 0 0</forward>
      <upward>0 0 1</upward>
      <link_name>base_link</link_name>
      <control_joint_name>servo_3</control_joint_name>
      <control_joint_rad_to_cl>-0.4888</control_joint_rad_to_cl> <!-- __corny: -0.4888, p4: -0.898, big difference -->
    </plugin>
    <plugin
      filename="gz-sim-joint-position-controller-system" name="gz::sim::systems::JointPositionController">
      <joint_name>servo_3</joint_name>
      <sub_topic>servo_3</sub_topic>
    </plugin>
    <!-- Winglets -->
    <plugin filename="gz-sim-lift-drag-system" name="gz::sim::systems::LiftDrag">
        <!-- Winglet Left -->
      <a0>0.</a0>
      <cla>4.752798721</cla> <!-- Muss auf Winglet Fläche referenziert sein! Hier habe ich Cessna Wert genutzt-->
      <cda>0.6417112299</cda> <!-- Cessna Wert -->
      <cma>0</cma> <!--__corny: -4.6, p4: 0-->
      <alpha_stall>0.2094</alpha_stall> <!-- <14deg for safety, actually 15.3deg overal config-->
      <cla_stall>-1.428</cla_stall> <!-- das ist alt: __corny: -1.428/rad, p4: -2.1001-->
      <cda_stall>-0.9233984055</cda_stall> <!-- Cessna Wert -->
      <cma_stall>0</cma_stall> <!-- nicht modellierbar -->
      <cp>0.665 1.7 0.089</cp> <!-- cp relativ zu base link (Schwerpunkt); hier ist z Position z=0 von main Wing -->
      <area>0.04865</area>
      <air_density>1.2</air_density>
      <forward>1 0 0</forward> <!-- das checken! -->
      <upward>0 1 0</upward> <!-- das checken! -->
      <link_name>base_link</link_name>
    </plugin>
    
    <plugin filename="gz-sim-lift-drag-system" name="gz::sim::systems::LiftDrag">
        <!-- Winglet Right-->
      <a0>0.</a0>
      <cla>4.752798721</cla> <!-- Muss auf Winglet Fläche referenziert sein! Hier habe ich Cessna Wert genutzt-->
      <cda>0.6417112299</cda> <!-- Cessna Wert -->
      <cma>0</cma> <!--__corny: -4.6, p4: 0-->
      <alpha_stall>0.2094</alpha_stall> <!-- <14deg for safety, actually 15.3deg overal config-->
      <cla_stall>-1.428</cla_stall> <!-- das ist alt: __corny: -1.428/rad, p4: -2.1001-->
      <cda_stall>-0.9233984055</cda_stall> <!-- Cessna Wert -->
      <cma_stall>0</cma_stall> <!-- nicht modellierbar -->
      <cp>0.665 -1.7 0.089</cp> <!-- cp relativ zu base link (Schwerpunkt); hier ist z Position z=0 von main Wing -->
      <area>0.04865</area>
      <air_density>1.2</air_density>
      <forward>1 0 0</forward> <!-- das checken! -->
      <upward>0 1 0</upward> <!-- das checken! -->
      <link_name>base_link</link_name>
    </plugin>

<!-- Motor Models -->
    <!-- Motor 0 -->
    <plugin 
        filename="gz-sim-multicopter-motor-model-system"
        name="gz::sim::systems::MulticopterMotorModel">
      <jointName>rotor_0_joint</jointName>
      <linkName>rotor_0</linkName>
      <turningDirection>ccw</turningDirection>
      <timeConstantUp>0.0125</timeConstantUp>
      <timeConstantDown>0.025</timeConstantDown>
      <maxRotVelocity>744</maxRotVelocity> <!-- omega in rad/s -->
      <motorConstant>7.2597e-05</motorConstant>
      <momentConstant>0.06</momentConstant> <!-- dragTorque = thrust*momentConstant -->
      <commandSubTopic>command/motor_speed</commandSubTopic>
      <motorNumber>0</motorNumber>
      <rotorDragCoefficient>0.000106428</rotorDragCoefficient> 
      <rollingMomentCoefficient>1e-06</rollingMomentCoefficient>
      <rotorVelocitySlowdownSim>20</rotorVelocitySlowdownSim>
      <motorType>velocity</motorType>
    </plugin>
    <!-- Motor 1 -->
    <plugin 
        filename="gz-sim-multicopter-motor-model-system" 
        name="gz::sim::systems::MulticopterMotorModel">
      <jointName>rotor_1_joint</jointName>
      <linkName>rotor_1</linkName>
      <turningDirection>cw</turningDirection>
      <timeConstantUp>0.0125</timeConstantUp>
      <timeConstantDown>0.025</timeConstantDown>
      <maxRotVelocity>744</maxRotVelocity> <!-- omega in rad/s -->
      <motorConstant>7.2597e-05</motorConstant>
      <momentConstant>0.06</momentConstant> <!-- dragTorque = thrust*momentConstant -->
      <commandSubTopic>command/motor_speed</commandSubTopic>
      <motorNumber>1</motorNumber>
      <rotorDragCoefficient>0.000106428</rotorDragCoefficient>
      <rollingMomentCoefficient>1e-06</rollingMomentCoefficient>
      <rotorVelocitySlowdownSim>20</rotorVelocitySlowdownSim>
      <motorType>velocity</motorType>
    </plugin>
    <!-- Motor 2 -->
    <plugin
        filename="gz-sim-multicopter-motor-model-system"
        name="gz::sim::systems::MulticopterMotorModel">
      <jointName>rotor_2_joint</jointName>
      <linkName>rotor_2</linkName>
      <turningDirection>cw</turningDirection>
      <timeConstantUp>0.0125</timeConstantUp>
      <timeConstantDown>0.025</timeConstantDown>
      <maxRotVelocity>744</maxRotVelocity> <!-- omega in rad/s -->
      <motorConstant>7.2597e-05</motorConstant>
      <momentConstant>0.06</momentConstant> <!-- dragTorque = thrust*momentConstant -->
      <commandSubTopic>command/motor_speed</commandSubTopic>
      <motorNumber>1</motorNumber> <!-- wird auch auf 1 gestellt, damit wir PX4 nutzen können -->
      <rotorDragCoefficient>0.000106428</rotorDragCoefficient>
      <rollingMomentCoefficient>1e-06</rollingMomentCoefficient>
      <rotorVelocitySlowdownSim>20</rotorVelocitySlowdownSim>
      <motorType>velocity</motorType>
    </plugin>
    <!-- Motor 3 -->
    <plugin
        filename="gz-sim-multicopter-motor-model-system"
        name="gz::sim::systems::MulticopterMotorModel">
      <jointName>rotor_3_joint</jointName>
      <linkName>rotor_3</linkName>
      <turningDirection>ccw</turningDirection>
      <timeConstantUp>0.0125</timeConstantUp>
      <timeConstantDown>0.025</timeConstantDown>
      <maxRotVelocity>744</maxRotVelocity> <!-- omega in rad/s -->
      <motorConstant>7.2597e-05</motorConstant> 
      <momentConstant>0.06</momentConstant> <!-- dragTorque = thrust*momentConstant -->
      <commandSubTopic>command/motor_speed</commandSubTopic>
      <motorNumber>2</motorNumber>
      <rotorDragCoefficient>0.000106428</rotorDragCoefficient>
      <rollingMomentCoefficient>1e-06</rollingMomentCoefficient>
      <rotorVelocitySlowdownSim>20</rotorVelocitySlowdownSim>
      <motorType>velocity</motorType>
    </plugin>
    <!-- Motor 4 -->
    <plugin
        filename="gz-sim-multicopter-motor-model-system"
        name="gz::sim::systems::MulticopterMotorModel">
      <jointName>rotor_4_joint</jointName>
      <linkName>rotor_4</linkName>
      <turningDirection>cw</turningDirection>
      <timeConstantUp>0.0125</timeConstantUp>
      <timeConstantDown>0.025</timeConstantDown>
      <maxRotVelocity>744</maxRotVelocity> <!-- omega in rad/s -->
      <motorConstant>7.2597e-05</motorConstant>
      <momentConstant>0.06</momentConstant> <!-- dragTorque = thrust*momentConstant -->
      <commandSubTopic>command/motor_speed</commandSubTopic>
      <motorNumber>3</motorNumber>
      <rotorDragCoefficient>0.000106428</rotorDragCoefficient>
      <rollingMomentCoefficient>1e-06</rollingMomentCoefficient>
      <rotorVelocitySlowdownSim>20</rotorVelocitySlowdownSim>
      <motorType>velocity</motorType>
    </plugin>
    <!-- Motor 5 -->
    <plugin
        filename="gz-sim-multicopter-motor-model-system"
        name="gz::sim::systems::MulticopterMotorModel">
      <jointName>rotor_5_joint</jointName>
      <linkName>rotor_5</linkName>
      <turningDirection>ccw</turningDirection>
      <timeConstantUp>0.0125</timeConstantUp>
      <timeConstantDown>0.025</timeConstantDown>
      <maxRotVelocity>744</maxRotVelocity> <!-- omega in rad/s -->
      <motorConstant>7.2597e-05</motorConstant>
      <momentConstant>0.06</momentConstant> <!-- dragTorque = thrust*momentConstant -->
      <commandSubTopic>command/motor_speed</commandSubTopic>
      <motorNumber>4</motorNumber>
      <rotorDragCoefficient>0.000106428</rotorDragCoefficient>
      <rollingMomentCoefficient>1e-06</rollingMomentCoefficient>
      <rotorVelocitySlowdownSim>20</rotorVelocitySlowdownSim>
      <motorType>velocity</motorType>
    </plugin>
    <!-- Motor 6 -->
    <plugin
        filename="gz-sim-multicopter-motor-model-system"
        name="gz::sim::systems::MulticopterMotorModel">
      <jointName>rotor_6_joint</jointName>
      <linkName>rotor_6</linkName>
      <turningDirection>ccw</turningDirection>
      <timeConstantUp>0.0125</timeConstantUp>
      <timeConstantDown>0.025</timeConstantDown>
      <maxRotVelocity>744</maxRotVelocity> <!-- omega in rad/s -->
      <motorConstant>7.2597e-05</motorConstant>
      <momentConstant>0.06</momentConstant> <!-- dragTorque = thrust*momentConstant -->
      <commandSubTopic>command/motor_speed</commandSubTopic>
      <motorNumber>4</motorNumber>  <!-- wird auch auf 4 gestellt, damit wir PX4 nutzen können -->
      <rotorDragCoefficient>0.000106428</rotorDragCoefficient>
      <rollingMomentCoefficient>1e-06</rollingMomentCoefficient>
      <rotorVelocitySlowdownSim>20</rotorVelocitySlowdownSim>
      <motorType>velocity</motorType>
    </plugin>
    <!-- Motor 7 -->
    <plugin
        filename="gz-sim-multicopter-motor-model-system"
        name="gz::sim::systems::MulticopterMotorModel">
      <jointName>rotor_7_joint</jointName>
      <linkName>rotor_7</linkName>
      <turningDirection>cw</turningDirection>
      <timeConstantUp>0.0125</timeConstantUp>
      <timeConstantDown>0.025</timeConstantDown>
      <maxRotVelocity>744</maxRotVelocity> <!-- omega in rad/s -->
      <motorConstant>7.2597e-05</motorConstant>
      <momentConstant>0.06</momentConstant> <!-- dragTorque = thrust*momentConstant -->
      <commandSubTopic>command/motor_speed</commandSubTopic>
      <motorNumber>5</motorNumber>
      <rotorDragCoefficient>0.000106428</rotorDragCoefficient>
      <rollingMomentCoefficient>1e-06</rollingMomentCoefficient>
      <rotorVelocitySlowdownSim>20</rotorVelocitySlowdownSim>
      <motorType>velocity</motorType>
    </plugin>
    <!-- Pusher Motor left -->
    <plugin
        filename="gz-sim-multicopter-motor-model-system"
        name="gz::sim::systems::MulticopterMotorModel">
      <jointName>rotor_8_joint</jointName>
      <linkName>rotor_8</linkName>
      <turningDirection>cw</turningDirection>
      <timeConstantUp>0.0125</timeConstantUp>
      <timeConstantDown>0.025</timeConstantDown>
      <maxRotVelocity>388</maxRotVelocity> <!-- omega in rad/s -->
      <motorConstant>1.703e-04</motorConstant>
      <momentConstant>0.01</momentConstant> <!-- dragTorque = thrust*momentConstant -->
      <commandSubTopic>command/motor_speed</commandSubTopic>
      <motorNumber>6</motorNumber>
      <rotorDragCoefficient>0.000106428</rotorDragCoefficient>
      <rollingMomentCoefficient>1e-06</rollingMomentCoefficient>
      <rotorVelocitySlowdownSim>20</rotorVelocitySlowdownSim>
      <motorType>velocity</motorType>
    </plugin>
    <!-- Pusher Motor right -->
    <plugin
        filename="gz-sim-multicopter-motor-model-system"
        name="gz::sim::systems::MulticopterMotorModel">
      <jointName>rotor_9_joint</jointName>
      <linkName>rotor_9</linkName>
      <turningDirection>ccw</turningDirection>
      <timeConstantUp>0.0125</timeConstantUp>
      <timeConstantDown>0.025</timeConstantDown>
      <maxRotVelocity>388</maxRotVelocity> <!-- omega in rad/s -->
      <motorConstant>1.703e-04</motorConstant>
      <momentConstant>0.01</momentConstant> <!-- dragTorque = thrust*momentConstant -->
      <commandSubTopic>command/motor_speed</commandSubTopic>
      <motorNumber>6</motorNumber>
      <rotorDragCoefficient>0.000106428</rotorDragCoefficient>
      <rollingMomentCoefficient>1e-06</rollingMomentCoefficient>
      <rotorVelocitySlowdownSim>20</rotorVelocitySlowdownSim>
      <motorType>velocity</motorType>
    </plugin>
    <static>0</static>
  </model>

</sdf>

<!-- Neuer Test -->




